2022-10-12 12:28:06,063 INFO    StreamThr :11588 [internal.py:wandb_internal():88] W&B internal server running at pid: 11588, started at: 2022-10-12 12:28:06.060344
2022-10-12 12:28:06,073 DEBUG   HandlerThread:11588 [handler.py:handle_request():138] handle_request: status
2022-10-12 12:28:06,088 DEBUG   SenderThread:11588 [sender.py:send_request():317] send_request: status
2022-10-12 12:28:06,098 DEBUG   SenderThread:11588 [sender.py:send():303] send: header
2022-10-12 12:28:06,099 INFO    WriterThread:11588 [datastore.py:open_for_write():75] open: C:\Users\AsadMehmood\OneDrive - kyndryl\Python Scripts\mlops_work\MLOps-Training\08 ECR\outputs\2022-10-12\12-27-44\wandb\run-20221012_122805-t0clu0eu\run-t0clu0eu.wandb
2022-10-12 12:28:06,401 DEBUG   SenderThread:11588 [sender.py:send():303] send: run
2022-10-12 12:28:06,413 INFO    SenderThread:11588 [sender.py:_maybe_setup_resume():593] checking resume status for techwithshadab/MLOPS AWS/t0clu0eu
2022-10-12 12:28:07,950 ERROR   SenderThread:11588 [internal_api.py:execute():216] 404 response executing GraphQL.
2022-10-12 12:28:07,950 ERROR   SenderThread:11588 [internal_api.py:execute():217] {"errors":[{"message":"project not found","path":["upsertBucket"]}],"data":{"upsertBucket":null}}
2022-10-12 12:28:08,426 INFO    WriterThread:11588 [datastore.py:close():279] close: C:\Users\AsadMehmood\OneDrive - kyndryl\Python Scripts\mlops_work\MLOps-Training\08 ECR\outputs\2022-10-12\12-27-44\wandb\run-20221012_122805-t0clu0eu\run-t0clu0eu.wandb
2022-10-12 12:28:08,426 INFO    HandlerThread:11588 [handler.py:finish():814] shutting down handler
2022-10-12 12:28:08,426 ERROR   StreamThr :11588 [internal.py:wandb_internal():163] Thread SenderThread:
Traceback (most recent call last):
  File "C:\Anaconda3\envs\tf-torch\lib\site-packages\wandb\sdk\lib\retry.py", line 113, in __call__
    result = self._call_fn(*args, **kwargs)
  File "C:\Anaconda3\envs\tf-torch\lib\site-packages\wandb\sdk\internal\internal_api.py", line 213, in execute
    return self.client.execute(*args, **kwargs)  # type: ignore
  File "C:\Anaconda3\envs\tf-torch\lib\site-packages\wandb\vendor\gql-0.2.0\wandb_gql\client.py", line 52, in execute
    result = self._get_result(document, *args, **kwargs)
  File "C:\Anaconda3\envs\tf-torch\lib\site-packages\wandb\vendor\gql-0.2.0\wandb_gql\client.py", line 60, in _get_result
    return self.transport.execute(document, *args, **kwargs)
  File "C:\Anaconda3\envs\tf-torch\lib\site-packages\wandb\vendor\gql-0.2.0\wandb_gql\transport\requests.py", line 39, in execute
    request.raise_for_status()
  File "C:\Anaconda3\envs\tf-torch\lib\site-packages\requests\models.py", line 1021, in raise_for_status
    raise HTTPError(http_error_msg, response=self)
requests.exceptions.HTTPError: 404 Client Error: Not Found for url: https://api.wandb.ai/graphql

During handling of the above exception, another exception occurred:

Traceback (most recent call last):
  File "C:\Anaconda3\envs\tf-torch\lib\site-packages\wandb\apis\normalize.py", line 26, in wrapper
    return func(*args, **kwargs)
  File "C:\Anaconda3\envs\tf-torch\lib\site-packages\wandb\sdk\internal\internal_api.py", line 1474, in upsert_run
    response = self.gql(
  File "C:\Anaconda3\envs\tf-torch\lib\site-packages\wandb\sdk\lib\retry.py", line 129, in __call__
    retry_timedelta_triggered = check_retry_fn(e)
  File "C:\Anaconda3\envs\tf-torch\lib\site-packages\wandb\util.py", line 1030, in check_retry_fn
    return fallback_retry_fn(e)
  File "C:\Anaconda3\envs\tf-torch\lib\site-packages\wandb\util.py", line 977, in no_retry_auth
    raise CommError("Permission denied, ask the project owner to grant you access")
wandb.errors.CommError: Permission denied, ask the project owner to grant you access

During handling of the above exception, another exception occurred:

Traceback (most recent call last):
  File "C:\Anaconda3\envs\tf-torch\lib\site-packages\wandb\sdk\internal\internal_util.py", line 50, in run
    self._run()
  File "C:\Anaconda3\envs\tf-torch\lib\site-packages\wandb\sdk\internal\internal_util.py", line 101, in _run
    self._process(record)
  File "C:\Anaconda3\envs\tf-torch\lib\site-packages\wandb\sdk\internal\internal.py", line 308, in _process
    self._sm.send(record)
  File "C:\Anaconda3\envs\tf-torch\lib\site-packages\wandb\sdk\internal\sender.py", line 305, in send
    send_handler(record)
  File "C:\Anaconda3\envs\tf-torch\lib\site-packages\wandb\sdk\internal\sender.py", line 797, in send_run
    self._init_run(run, config_value_dict)
  File "C:\Anaconda3\envs\tf-torch\lib\site-packages\wandb\sdk\internal\sender.py", line 823, in _init_run
    server_run, inserted, server_messages = self._api.upsert_run(
  File "C:\Anaconda3\envs\tf-torch\lib\site-packages\wandb\apis\normalize.py", line 62, in wrapper
    raise CommError(message, err).with_traceback(sys.exc_info()[2])
  File "C:\Anaconda3\envs\tf-torch\lib\site-packages\wandb\apis\normalize.py", line 26, in wrapper
    return func(*args, **kwargs)
  File "C:\Anaconda3\envs\tf-torch\lib\site-packages\wandb\sdk\internal\internal_api.py", line 1474, in upsert_run
    response = self.gql(
  File "C:\Anaconda3\envs\tf-torch\lib\site-packages\wandb\sdk\lib\retry.py", line 129, in __call__
    retry_timedelta_triggered = check_retry_fn(e)
  File "C:\Anaconda3\envs\tf-torch\lib\site-packages\wandb\util.py", line 1030, in check_retry_fn
    return fallback_retry_fn(e)
  File "C:\Anaconda3\envs\tf-torch\lib\site-packages\wandb\util.py", line 977, in no_retry_auth
    raise CommError("Permission denied, ask the project owner to grant you access")
wandb.errors.CommError: Permission denied, ask the project owner to grant you access
